Workbook

Sheet TRACKER
A1: ORDER INFORMATION | J1: ① ACTIVE SO & FG CREATION | L1: ② BOM CREATION | N1: ③ SMV UPDATE | P1: ④ PLANT EXT & CODE CHANGE | R1: ⑤ CR RELEASE | T1: ⑥ PO | V1: REMARKS / NOTES
A2: BUY ORDER NAME | B2: RESPONSIBLE | C2: BUY QTY | D2: TOTAL SO | E2: TOTAL FG | F2: REF ACTIVE FG | G2: DEADLINE | H2: OVERALL STATUS | I2: CURRENT STEP | J2: DATE DONE | K2: STATUS | L2: DATE DONE | M2: STATUS | N2: DATE DONE | O2: STATUS | P2: DATE DONE | Q2: STATUS | R2: DATE DONE | S2: STATUS | T2: DATE DONE | U2: STATUS | V2: REMARKS / NOTES
A3: SE GYMSHARK – SS26 Soft Sculpt Re-buy – Shadowline | C3: 7713 | D3: 4 | E3: 1 | G3: 30.04.2026 | H3: COMPLETE | I3: ✅ ALL COMPLETE | K3: ✅ DONE | M3: ✅ DONE | O3: ✅ DONE | Q3: ✅ DONE | S3: ✅ DONE | U3: ✅ DONE | V3: SMV follow-up done. Plant change pending (follow-up done). Currently at Step 4.
A4: SE GYMSHARK - AW26 - SOFT SCULPT MAR BUY-1 - Shadowline | C4: 20997 | D4: 74 | E4: 10 | F4: 7001473758 | G4: 18.06.2026 | H4: COMPLETE | K4: ✅ DONE | M4: ✅ DONE | O4: ✅ DONE | Q4: ✅ DONE | S4: ✅ DONE | U4: ✅ DONE
A5: SE GYMSHARK - SS26 Shadow Buy - Asialine | C5: 46704 | D5: 28 | E5: 7 | F5: 7001445952 | G5: 24.04.2026 | H5: COMPLETE | I5: → ④ PLANT EXT & CODE CHANGE | K5: ✅ DONE | M5: ✅ DONE | O5: ✅ DONE | Q5: ✅ DONE | S5: ✅ DONE | U5: ✅ DONE | V5: Steps 1–3 done. Plant code error FIXED – mailed to Kishori. At Step 4. REF FG: 7001445952.
A6: LULU – Sleekline – 6FA – Add Qtys | C6: 1709 | D6: 9 | E6: 4 | F6: 7001452177 | G6: 23.03.2026 | H6: COMPLETE | I6: → ④ PLANT EXT & CODE CHANGE | K6: ✅ DONE | M6: ✅ DONE | O6: ✅ DONE | Q6: ✅ DONE | S6: ✅ DONE | U6: ✅ DONE | V6: Active SO & FG DONE. BOM PROCESSING. Deadline: 23.03.2026.
A7: LW3DOBS- SLK | C7: 13935 | D7: 3 | E7: 1 | F7: 7001479673 | G7: 16.06.2026 | H7: COMPLETE | K7: ✅ DONE | M7: ✅ DONE | O7: ✅ DONE | Q7: ✅ DONE | S7: ✅ DONE | U7: ✅ DONE
A8: LULU -Seamless Orders - Sleekline - 6FA- later transfer | C8: 31697 | D8: 15 | E8: 5 | F8: 7001462606 | G8: 20.05.2026 | H8: COMPLETE | K8: ✅ DONE | M8: ✅ DONE | O8: ✅ DONE | Q8: ✅ DONE | S8: ✅ DONE | U8: ⏳ PENDING
A9: SE GYMSHARK – SS26 Shadow DEC Buy – Contourline | C9: 25561 | D9: 24 | E9: 7 | F9: 7001443456 | G9: 20.04.2026 | H9: COMPLETE | I9: ✅ ALL COMPLETE | K9: ✅ DONE | M9: ✅ DONE | O9: ✅ DONE | Q9: ✅ DONE | S9: ✅ DONE | U9: ✅ DONE | V9: 🎉 FULLY COMPLETE – PO DONE. REF FG: 7001443456.
A10: LULU – Sleekline – 6SP – Add Qtys | C10: 25651 | D10: 16 | E10: 5 | F10: 7001452172 | G10: 20.03.2026 | H10: COMPLETE | I10: → ⑤ CR RELEASE | K10: ✅ DONE | M10: ✅ DONE | O10: ✅ DONE | Q10: ✅ DONE | S10: ✅ DONE | U10: ✅ DONE | V10: Active SO & FG DONE. BOM next. Deadline: 20.03.2026.
A11: SE GYMSHARK 6AW- GEO BUY MARCH-- SLK | C11: 54228 | D11: 110 | E11: 18 | F11: 7001474027 | G11: 06.07.2026 | H11: COMPLETE | K11: ✅ DONE | M11: ✅ DONE | O11: ✅ DONE | Q11: ✅ DONE | S11: ✅ DONE | U11: ✅ DONE
A12: WI26-LULU ADD - SLK | B12: LAKSHAN | C12: 5942 | D12: 12 | E12: 4 | F12: 7001488845 | G12: 02.07.2026 | H12: IN PROGRESS | K12: ✅ DONE | M12: IN PROGRESS
A13: SE GYMSHARK - SS26 Soft Sculpt - B2C7T - Contourline | C13: 19273 | E13: 12 | F13: 7001462962 | G13: 11.05.2026 | H13: COMPLETE | K13: ✅ DONE | M13: ✅ DONE | O13: ✅ DONE | Q13: ✅ DONE | S13: ✅ DONE | U13: ✅ DONE
A14: LULU – Sleekline – FA26 – LW1GOWS – Transfer CNTL | C14: 46068 | D14: 40 | E14: 12 | F14: 7001449920 | G14: 10.04.2026 | H14: COMPLETE | I14: → ② BOM CREATION | K14: ✅ DONE | M14: ✅ DONE | O14: ✅ DONE | Q14: ✅ DONE | S14: ✅ DONE | U14: ✅ DONE | V14: Active SO & FG DONE. BOM PENDING – needs Dilshan's assist (4 fabrics). Deadline: 10.04.2026.
A15: FALL 26 MAR LULU Chase-SLK | C15: 7189 | D15: 11 | E15: 4 | F15: 7001477483 | G15: 02.06.2026 | H15: COMPLETE | I15: → ⑤ CR RELEASE | K15: ✅ DONE | M15: ✅ DONE | O15: ✅ DONE | Q15: ✅ DONE | S15: ✅ DONE | U15: ✅ DONE
A16: SE GYMSHARK – AW26 Shadow JAN Buy – Contourline | C16: 23916 | D16: 45 | E16: 3 | F16: 7001446070 | G16: — | H16: COMPLETE | I16: → ② BOM CREATION | K16: ✅ DONE | M16: ✅ DONE | O16: ✅ DONE | Q16: ✅ DONE | S16: ✅ DONE | U16: ✅ DONE | V16: Active SO & FG done (except 2 samples). BOM file received from Suraj. REF FG: 7001446070.
A17: SE GYMSHARK – AW26 Distance IYKYK Buy – Sleekline | C17: 8693 | D17: 32 | E17: 4 | F17: 7001447155 | G17: — | H17: COMPLETE | I17: → ④ PLANT EXT & CODE CHANGE | K17: ✅ DONE | M17: ✅ DONE | O17: ✅ DONE | Q17: ✅ DONE | S17: ✅ DONE | U17: ✅ DONE | V17: Steps 1–2 done. SMV UPDATE PENDING – follow-up done. REF FG: 7001447155.
A18: SE GYMSHARK – M26 ONYX Buy – Transfer from ASL | C18: 477 | D18: 4 | E18: 4 | G18: — | H18: COMPLETE | I18: → ⑥ PO | K18: ✅ DONE | M18: ✅ DONE | O18: ✅ DONE | Q18: ✅ DONE | S18: ✅ DONE | U18: ✅ DONE | V18: Steps 1–4 done. CR Release pending. PO pending. Urgent – fabric delay transfer from ASL.
A19: SE GYMSHARK – AW26 Shadow JAN Buy – Contourline (Add-on) | C19: 9588 | D19: 29 | E19: 3 | F19: 7001453015 | G19: — | H19: COMPLETE | I19: → ⑤ CR RELEASE | K19: ✅ DONE | M19: ✅ DONE | O19: ✅ DONE | Q19: ✅ DONE | S19: ✅ DONE | V19: Active SO & FG DONE. BOM next.
A20: SE GYMSHARK - AW26 - GEO BUY - Sleekline | C20: 98069 | D20: 239 | E20: 24 | F20: 7001453358 | H20: COMPLETE | K20: ✅ DONE | M20: ✅ DONE | O20: ✅ DONE | Q20: ✅ DONE | S20: ✅ DONE | U20: ✅ DONE
A21: LULU -Seamless Orders from H056 & H150 -FA26- Sleekline | C21: 622466 | D21: 728 | E21: 214 | F21: 7001425058 - H056 7001421659 - H150 | H21: COMPLETE | K21: ✅ DONE | M21: ✅ DONE | O21: ✅ DONE | Q21: ✅ DONE | S21: ✅ DONE | U21: ✅ DONE
A22: LULU -Seamless Orders from H150 -FA26- - Contourline | C22: 135883 | D22: 257 | E22: 40 | F22: 7001433766 | H22: ❌ BLOCKED | K22: ❌ BLOCKED | M22: ❌ BLOCKED | O22: ❌ BLOCKED | Q22: ❌ BLOCKED | S22: ❌ BLOCKED | U22: ❌ BLOCKED
A23: WI26-Chase-SLK | B23: LAKSHAN | C23: 84194 | D23: 38 | E23: 9 | F23: 7001488586 | G23: 02.07.2026 | H23: IN PROGRESS | K23: ✅ DONE | M23: IN PROGRESS
A24: SE GYMSHARK - 6AW- GEO Range- A4B5F & A5A2D | C24: 38532 | D24: 111 | E24: 14 | F24: 7001466707 | H24: COMPLETE | I24: → ⑤ CR RELEASE | K24: ✅ DONE | M24: ✅ DONE | O24: ✅ DONE | Q24: ✅ DONE | S24: ✅ DONE | U24: ✅ DONE
A25: SE GYMSHARK -6AW - Soft Sculpt MAR buy 1- SLK | B25: LAKSHAN | C25: 75891 | D25: 235 | E25: 27 | F25: 7001473550 | G25: 06.07.2026 | H25: IN PROGRESS | K25: ✅ DONE | M25: IN PROGRESS
A26: AW26 DISTANCE-A4B5F - SLK | C26: 1485 | D26: 7 | E26: 2 | F26: 7001479510 | H26: COMPLETE | I26: → ⑤ CR RELEASE | K26: ✅ DONE | M26: ✅ DONE | O26: ✅ DONE | Q26: ✅ DONE | S26: ✅ DONE | U26: ✅ DONE
A27: A1B2A transfer ASL to SLK | C27: 1715 | D27: 2 | E27: 2 | F27: 7001479503 | H27: COMPLETE | K27: ✅ DONE | M27: ✅ DONE | O27: ✅ DONE | Q27: ✅ DONE | S27: ✅ DONE | U27: ✅ DONE
A28: A1B5B transfer from CNTR to SLK | C28: 21025 | D28: 34 | E28: 6 | F28: 7001479505 | H28: COMPLETE | I28: → ⑤ CR RELEASE | K28: ✅ DONE | M28: IN PROGRESS | O28: ⏳ PENDING | Q28: ⏳ PENDING | S28: ⏳ PENDING | U28: ⏳ PENDING
A29: LULU -Seamless Orders - Sleekline - WI26 buy Allocation | C29: 477362 | D29: 582 | E29: 85 | F29: 7001475267 | G29: 18.07.2026 | H29: IN PROGRESS | K29: ✅ DONE | M29: IN PROGRESS
A30: SE GYMSHARK -AW26 - Shadow MAR buy - SLK | C30: 36679 | D30: 53 | E30: 7 | F30: x | H30: ⏳ PENDING | K30: ✅ DONE
A31: SE GYMSHARK -6AW- Shadow buy - SLK | C31: 8998 | D31: 31 | E31: 4 | F31: 7001474020 | H31: ⏳ PENDING | K31: ✅ DONE | M31: ✅ DONE | O31: ✅ DONE | Q31: ✅ DONE | S31: ✅ DONE
A32: AW26 SOFT SCULPT MARBUY - B6C3Y - CONTRL | B32: LAKSHAN | C32: 62359 | D32: 161 | E32: 20 | F32: 7001480448 | H32: ⏳ PENDING
A33: AW26 SOFT SCULPT MARBUY - B7C2V - SLK | B33: LAKSHAN | C33: 15101 | D33: 76 | E33: 10 | F33: 7001480453 | H33: ⏳ PENDING
A34: AW26 SOFTSCULPT MARBUY2&3-B6C4T- CONTRL | B34: LAKSHAN | C34: 62359 | D34: 81 | E34: 10 | F34: 7001480448 | H34: ⏳ PENDING
A35: Shadowline -B6C4T | B35: LAKSHAN | C35: 37162 | D35: 81 | E35: 11 | F35: 7001491130 | H35: ⏳ PENDING | K35: ✅ DONE
A36: Gymshark TRNF to ASL from SLK | C36: 451 | D36: 3 | E36: 2 | F36: 7001480457 | H36: ⏳ PENDING
A37: AW26 Shadow MayBuy1-SLK | C37: 22986 | D37: 12 | E37: 4 | F37: 7001480455 | H37: ⏳ PENDING
F38: 53358
A39: =COUNTA(A3:A37) -> 35 | C39: =SUM(C3:C37) -> 2152058 | E39: =COUNTIF(H3:H37,"IN PROGRESS") -> 4 | F39: =COUNTIF(H3:H37,"BLOCKED") -> 0 | H39: =COUNTIF(H3:H37,"COMPLETE") -> 18
A41: ⚙️ 6-STEP BUY COMPLETION PROCESS FLOW → Each column pair = DATE DONE + STATUS → Fill date when step is completed
...

Sheet DASHBOARD
B6: TOTAL BUYS | C6: TOTAL QTY | D6: ✅ COMPLETE | E6: 🔵 IN PROGRESS | F6: ❌ BLOCKED
B9: =TRACKER!A39 -> 35 | C9: =TRACKER!C39 -> 2152058 | D9: =TRACKER!D39 -> 0 | E9: =TRACKER!E39 -> 4 | F9: =TRACKER!F39 -> 0
B18: ⚙️ ACTIVE ORDERS PER STEP
B20: ① ACTIVE SO & FG CREATION | E20: =COUNTIF(TRACKER!K3:K37,"✅ DONE") -> 29 | F20: orders active
B22: ② BOM CREATION | E22: =COUNTIF(TRACKER!M3:M37,"✅ DONE") -> 22 | F22: orders active
B24: ③ SMV UPDATE | E24: =COUNTIF(TRACKER!O3:O37,"✅ DONE") -> 22 | F24: orders active
B26: ④ PLANT EXT & CODE CHANGE | E26: =COUNTIF(TRACKER!Q3:Q37,"✅ DONE") -> 22 | F26: orders active
B28: ⑤ CR RELEASE | E28: =COUNTIF(TRACKER!S3:S37,"✅ DONE") -> 22 | F28: orders active
B30: ⑥ PO | E30: =COUNTIF(TRACKER!U3:U37,"🔄 IN PROGRESS")+COUNTIF(TRACKER!U3:U37,"✅ DONE") -> 19 | F30: orders active
B33: 📋 STATUS BREAKDOWN
B35: COMPLETE | E35: =COUNTIF(TRACKER!H3:H37,"COMPLETE") -> 18 | F35: orders
B37: IN PROGRESS | E37: =COUNTIF(TRACKER!H3:H37,"IN PROGRESS") -> 4 | F37: orders
B39: BLOCKED | E39: =COUNTIF(TRACKER!H3:H37,"BLOCKED") -> 0 | F39: orders
B41: NOT STARTED | E41: =COUNTIF(TRACKER!H3:H37,"NOT STARTED") -> 0 | F41: orders
B43: OVERDUE | E43: =COUNTIF(TRACKER!H3:H37,"OVERDUE") -> 0 | F43: orders
B50: ⛔ ITEMS NEEDING ATTENTION
B52: BUY ORDER | E52: AT STEP | F52: STATUS
B53: SE VUORI – VM1198 – Transfer to Contourline | E53: ⛔ ① ACTIVE SO & FG | F53: BLOCKED
B54: → Open 'TRACKER' sheet to update step dates and statuses

Sheet REFERENCE
A1: GYMSHARK – PO / SO REFERENCE DATA (from original Sheet1)
A2: SO / REF NO | B2: TYPE | C2: STYLE 1 | D2: STYLE 2 | E2: PO NUMBER | F2: UNITS | H2: SUPPLIER | I2: COLOURWAY | J2: MODE | K2: QTY
A3: 1001617763 | B3: 10 | D3: AMITY | E3: BB2J | F3: Sea | G3: 448
A4: GYMSHARK | B4: Bulk | C4: B5B9N | D4: B5B9N | E4: 1001617764 | F4: 10 | H4: AMITY | I4: NBZG | J4: Sea | K4: 117
A5: GYMSHARK | B5: Bulk | C5: B4B7G | D5: B4B7G | E5: 1001617766 | F5: 10 | H5: AMITY | I5: NBZG | J5: Sea | K5: 623
A6: GYMSHARK | B6: Bulk | C6: B4B7G | D6: B4B7G | E6: 1001617767 | F6: 10 | H6: AMITY | I6: NBZG | J6: Sea | K6: 410
A7: GYMSHARK | B7: Bulk | C7: B4B7G | D7: B4B7G | E7: 1001617762 | F7: 10 | H7: AMITY | I7: NBZG | J7: Sea | K7: 185
E8: 1001617763
A10: Source: Original uploaded file – Sheet1. Retained as reference data only.
